<?xml version="1.0"?>
<robot name="tilting_plate">

  <!-- base_link -->
  <link name="base_link">
    <inertial>
      <mass value="5.0"/>
      <inertia
          ixx="0.1208" ixy="0.0" ixz="0.0"
          iyy="0.1208" iyz="0.0" izz="0.0333"/>
      <origin xyz="0 0 0.25" rpy="0 0 0"/>
    </inertial>
    <visual>
      <geometry>
        <box size="0.2 0.2 0.5"/>
      </geometry>
      <origin rpy="0 0 0" xyz="0 0 0.25"/>
      <material name="gray">
        <color rgba="0.5 0.5 0.5 1"/>
      </material>
    </visual>
    <collision>
      <geometry>
        <box size="0.2 0.2 0.5"/>
      </geometry>
    </collision>
  </link>

  <!-- pivot_link -->
  <link name="pivot_link">
    <inertial>
      <mass value="1.0"/>
      <inertia
          ixx="0.0010" ixy="0.0" ixz="0.0"
          iyy="0.0010" iyz="0.0" izz="0.0010"/>
      <origin xyz="0 0 0" rpy="0 0 0"/>
    </inertial>
    <visual>
      <geometry>
        <sphere radius="0.05"/>
      </geometry>
      <origin rpy="0 0 0" xyz="0 0 0"/>
      <material name="black">
        <color rgba="0 0 0 1"/>
      </material>
    </visual>
    <collision>
      <geometry>
        <sphere radius="0.05"/>
      </geometry>
    </collision>
  </link>

  <!-- plate -->
  <link name="plate_link">
    <inertial>
      <mass value="2.0"/>
      <inertia
          ixx="0.1683" ixy="0.0" ixz="0.0"
          iyy="0.1683" iyz="0.0" izz="0.3333"/>
      <origin xyz="0 0 0" rpy="0 0 0"/>
    </inertial>
    <visual>
      <origin rpy="0 0 0" xyz="0 0 0"/>
      <geometry>
        <box size="1.0 1.0 0.1"/>
      </geometry>
      <material name="blue">
        <color rgba="0 0 1 1"/>
      </material>
    </visual>
    <collision>
      <geometry>
        <box size="1.0 1.0 0.1"/>
      </geometry>
    </collision>
  </link>

  <!-- 基座到轴心的关节（Y轴旋转） -->
  <joint name="pivot_joint_y" type="revolute">
    <parent link="base_link"/>
    <child link="pivot_link"/>
    <origin xyz="0 0 0.6" rpy="0 0 0"/>
    <axis xyz="0 1 0"/>
    <limit lower="-0.5" upper="0.5" effort="1000" velocity="0.5"/>
  </joint>

  <!-- 轴心到平板的关节（X轴旋转） -->
  <joint name="plate_joint_x" type="revolute">
    <parent link="pivot_link"/>
    <child link="plate_link"/>
    <origin xyz="0 0 0" rpy="0 0 0"/>  <!-- 小偏移，确保不与基座碰撞 -->
    <axis xyz="1 0 0"/>
    <limit lower="-0.5" upper="0.5" effort="1000" velocity="0.5"/>
  </joint>

</robot>

  <!-- 虚拟的世界链接 -->
  <link name="world"/>
  <!-- 将基座固定到世界 -->
  <joint name="fixed_base" type="fixed">
    <parent link="world"/>
    <child link="base_link"/>
    <origin xyz="0 0 0" rpy="0 0 0"/>
  </joint>